Traceback (most recent call last):
Traceback (most recent call last):
  File "gearman_worker_save_file.py", line 62, in <module>
  File "gearman_worker_read_file.py", line 72, in <module>
    gearman_worker.work()    
gearman_worker.work()
  File "/Library/Python/2.7/site-packages/gearman/worker.py", line 83, in work
  File "/Library/Python/2.7/site-packages/gearman/worker.py", line 83, in work
    continue_working = self.poll_connections_until_stopped(worker_connections, continue_while_connections_alive, timeout=poll_timeout)
  File "/Library/Python/2.7/site-packages/gearman/connection_manager.py", line 203, in poll_connections_until_stopped
    continue_working = self.poll_connections_until_stopped(worker_connections, continue_while_connections_alive, timeout=poll_timeout)
  File "/Library/Python/2.7/site-packages/gearman/connection_manager.py", line 203, in poll_connections_until_stopped
    raise ServerUnavailable('Found no valid connections in list: %r' % self.connection_list)
gearman.errors.ServerUnavailable: Found no valid connections in list: [<GearmanConnection 127.0.0.1:4730 connected=False>]
    raise ServerUnavailable('Found no valid connections in list: %r' % self.connection_list)
gearman.errors.ServerUnavailable: Found no valid connections in list: [<GearmanConnection 127.0.0.1:4730 connected=False>]
Traceback (most recent call last):
  File "gearman_worker_read_file.py", line 72, in <module>
    gearman_worker.work()
  File "/Library/Python/2.7/site-packages/gearman/worker.py", line 83, in work
Traceback (most recent call last):
Traceback (most recent call last):
  File "gearman_worker_save_file.py", line 62, in <module>
  File "gearman_worker_read_file.py", line 72, in <module>
    continue_working = self.poll_connections_until_stopped(worker_connections, continue_while_connections_alive, timeout=poll_timeout)
  File "/Library/Python/2.7/site-packages/gearman/connection_manager.py", line 203, in poll_connections_until_stopped
        gearman_worker.work()gearman_worker.work()

  File "/Library/Python/2.7/site-packages/gearman/worker.py", line 83, in work
  File "/Library/Python/2.7/site-packages/gearman/worker.py", line 83, in work
    raise ServerUnavailable('Found no valid connections in list: %r' % self.connection_list)
        continue_working = self.poll_connections_until_stopped(worker_connections, continue_while_connections_alive, timeout=poll_timeout)
continue_working = self.poll_connections_until_stopped(worker_connections, continue_while_connections_alive, timeout=poll_timeout)
gearman.errors  File "/Library/Python/2.7/site-packages/gearman/connection_manager.py", line 203, in poll_connections_until_stopped
  File "/Library/Python/2.7/site-packages/gearman/connection_manager.py", line 203, in poll_connections_until_stopped
.ServerUnavailable: Found no valid connections in list: [<GearmanConnection 127.0.0.1:4730 connected=False>]
    raise ServerUnavailable('Found no valid connections in list: %r' % self.connection_list)
    raise ServerUnavailable('Found no valid connections in list: %r' % self.connection_list)
gearman.errors.ServerUnavailablegearman.errors: .Found no valid connections in list: [<GearmanConnection 127.0.0.1:4730 connected=False>]ServerUnavailable
: Found no valid connections in list: [<GearmanConnection 127.0.0.1:4730 connected=False>]
Traceback (most recent call last):
  File "gearman_worker_save_file.py", line 62, in <module>
    gearman_worker.work()
  File "/Library/Python/2.7/site-packages/gearman/worker.py", line 83, in work
    continue_working = self.poll_connections_until_stopped(worker_connections, continue_while_connections_alive, timeout=poll_timeout)
  File "/Library/Python/2.7/site-packages/gearman/connection_manager.py", line 203, in poll_connections_until_stopped
    raise ServerUnavailable('Found no valid connections in list: %r' % self.connection_list)
gearman.errors.ServerUnavailable: Found no valid connections in list: [<GearmanConnection 127.0.0.1:4730 connected=False>]
Traceback (most recent call last):
  File "gearman_worker_read_file.py", line 72, in <module>
    gearman_worker.work()
  File "/Library/Python/2.7/site-packages/gearman/worker.py", line 83, in work
    continue_working = self.poll_connections_until_stopped(worker_connections, continue_while_connections_alive, timeout=poll_timeout)
  File "/Library/Python/2.7/site-packages/gearman/connection_manager.py", line 203, in poll_connections_until_stopped
    raise ServerUnavailable('Found no valid connections in list: %r' % self.connection_list)
gearman.errors.ServerUnavailable: Found no valid connections in list: [<GearmanConnection 127.0.0.1:4730 connected=False>]
Traceback (most recent call last):
  File "gearman_worker_save_file.py", line 62, in <module>
    gearman_worker.work()
  File "/Library/Python/2.7/site-packages/gearman/worker.py", line 83, in work
    continue_working = self.poll_connections_until_stopped(worker_connections, continue_while_connections_alive, timeout=poll_timeout)
  File "/Library/Python/2.7/site-packages/gearman/connection_manager.py", line 203, in poll_connections_until_stopped
    raise ServerUnavailable('Found no valid connections in list: %r' % self.connection_list)
gearman.errors.ServerUnavailable: Found no valid connections in list: [<GearmanConnection 127.0.0.1:4730 connected=False>]
Traceback (most recent call last):
  File "gearman_worker_save_file.py", line 62, in <module>
    gearman_worker.work()
  File "/Library/Python/2.7/site-packages/gearman/worker.py", line 83, in work
    continue_working = self.poll_connections_until_stopped(worker_connections, continue_while_connections_alive, timeout=poll_timeout)
  File "/Library/Python/2.7/site-packages/gearman/connection_manager.py", line 203, in poll_connections_until_stopped
    raise ServerUnavailable('Found no valid connections in list: %r' % self.connection_list)
gearman.errors.ServerUnavailable: Found no valid connections in list: [<GearmanConnection 127.0.0.1:4730 connected=False>]
Traceback (most recent call last):
  File "gearman_worker_save_file.py", line 62, in <module>
    gearman_worker.work()
  File "/Library/Python/2.7/site-packages/gearman/worker.py", line 83, in work
    continue_working = self.poll_connections_until_stopped(worker_connections, continue_while_connections_alive, timeout=poll_timeout)
  File "/Library/Python/2.7/site-packages/gearman/connection_manager.py", line 203, in poll_connections_until_stopped
    raise ServerUnavailable('Found no valid connections in list: %r' % self.connection_list)
gearman.errors.ServerUnavailable: Found no valid connections in list: [<GearmanConnection 127.0.0.1:4730 connected=False>]
Traceback (most recent call last):
  File "gearman_worker_save_file.py", line 62, in <module>
    gearman_worker.work()
  File "/Library/Python/2.7/site-packages/gearman/worker.py", line 83, in work
    continue_working = self.poll_connections_until_stopped(worker_connections, continue_while_connections_alive, timeout=poll_timeout)
  File "/Library/Python/2.7/site-packages/gearman/connection_manager.py", line 203, in poll_connections_until_stopped
    raise ServerUnavailable('Found no valid connections in list: %r' % self.connection_list)
gearman.errors.ServerUnavailable: Found no valid connections in list: [<GearmanConnection 127.0.0.1:4730 connected=False>]
Traceback (most recent call last):
  File "gearman_worker_save_file.py", line 62, in <module>
    gearman_worker.work()
  File "/Library/Python/2.7/site-packages/gearman/worker.py", line 83, in work
    continue_working = self.poll_connections_until_stopped(worker_connections, continue_while_connections_alive, timeout=poll_timeout)
  File "/Library/Python/2.7/site-packages/gearman/connection_manager.py", line 203, in poll_connections_until_stopped
    raise ServerUnavailable('Found no valid connections in list: %r' % self.connection_list)
gearman.errors.ServerUnavailable: Found no valid connections in list: [<GearmanConnection 127.0.0.1:4730 connected=False>]
Traceback (most recent call last):
  File "gearman_worker_read_file.py", line 72, in <module>
    gearman_worker.work()
  File "/Library/Python/2.7/site-packages/gearman/worker.py", line 83, in work
    continue_working = self.poll_connections_until_stopped(worker_connections, continue_while_connections_alive, timeout=poll_timeout)
  File "/Library/Python/2.7/site-packages/gearman/connection_manager.py", line 203, in poll_connections_until_stopped
    raise ServerUnavailable('Found no valid connections in list: %r' % self.connection_list)
gearman.errors.ServerUnavailable: Found no valid connections in list: [<GearmanConnection 127.0.0.1:4730 connected=False>]
Traceback (most recent call last):
  File "gearman_worker_read_file.py", line 72, in <module>
    gearman_worker.work()
  File "/Library/Python/2.7/site-packages/gearman/worker.py", line 83, in work
    continue_working = self.poll_connections_until_stopped(worker_connections, continue_while_connections_alive, timeout=poll_timeout)
  File "/Library/Python/2.7/site-packages/gearman/connection_manager.py", line 203, in poll_connections_until_stopped
Traceback (most recent call last):
      File "gearman_worker_save_file.py", line 62, in <module>
raise ServerUnavailable('Found no valid connections in list: %r' % self.connection_list)
gearman.errors.ServerUnavailable: Found no valid connections in list: [<GearmanConnection 127.0.0.1:4730 connected=False>]
    gearman_worker.work()
  File "/Library/Python/2.7/site-packages/gearman/worker.py", line 83, in work
    continue_working = self.poll_connections_until_stopped(worker_connections, continue_while_connections_alive, timeout=poll_timeout)
  File "/Library/Python/2.7/site-packages/gearman/connection_manager.py", line 203, in poll_connections_until_stopped
    raise ServerUnavailable('Found no valid connections in list: %r' % self.connection_list)
gearman.errors.ServerUnavailable: Found no valid connections in list: [<GearmanConnection 127.0.0.1:4730 connected=False>]
Traceback (most recent call last):
  File "gearman_worker_read_file.py", line 72, in <module>
    gearman_worker.work()
  File "/Library/Python/2.7/site-packages/gearman/worker.py", line 83, in work
    continue_working = self.poll_connections_until_stopped(worker_connections, continue_while_connections_alive, timeout=poll_timeout)
  File "/Library/Python/2.7/site-packages/gearman/connection_manager.py", line 203, in poll_connections_until_stopped
    raise ServerUnavailable('Found no valid connections in list: %r' % self.connection_list)
gearman.errors.ServerUnavailable: Found no valid connections in list: [<GearmanConnection 127.0.0.1:4730 connected=False>]
Traceback (most recent call last):
  File "gearman_worker_read_file.py", line 72, in <module>
    gearman_worker.work()
  File "/Library/Python/2.7/site-packages/gearman/worker.py", line 83, in work
    continue_working = self.poll_connections_until_stopped(worker_connections, continue_while_connections_alive, timeout=poll_timeout)
  File "/Library/Python/2.7/site-packages/gearman/connection_manager.py", line 203, in poll_connections_until_stopped
    raise ServerUnavailable('Found no valid connections in list: %r' % self.connection_list)
gearman.errors.ServerUnavailable: Found no valid connections in list: [<GearmanConnection 127.0.0.1:4730 connected=False>]
Traceback (most recent call last):
  File "gearman_worker_read_file.py", line 72, in <module>
    gearman_worker.work()
  File "/Library/Python/2.7/site-packages/gearman/worker.py", line 83, in work
    continue_working = self.poll_connections_until_stopped(worker_connections, continue_while_connections_alive, timeout=poll_timeout)
  File "/Library/Python/2.7/site-packages/gearman/connection_manager.py", line 203, in poll_connections_until_stopped
    raise ServerUnavailable('Found no valid connections in list: %r' % self.connection_list)
gearman.errors.ServerUnavailable: Found no valid connections in list: [<GearmanConnection 127.0.0.1:4730 connected=False>]
Traceback (most recent call last):
  File "gearman_worker_save_file.py", line 62, in <module>
    gearman_worker.work()
  File "/Library/Python/2.7/site-packages/gearman/worker.py", line 83, in work
    continue_working = self.poll_connections_until_stopped(worker_connections, continue_while_connections_alive, timeout=poll_timeout)
  File "/Library/Python/2.7/site-packages/gearman/connection_manager.py", line 203, in poll_connections_until_stopped
    raise ServerUnavailable('Found no valid connections in list: %r' % self.connection_list)
Traceback (most recent call last):
gearman.errors  File "gearman_worker_read_file.py", line 72, in <module>
.ServerUnavailable: Found no valid connections in list: [<GearmanConnection 127.0.0.1:4730 connected=False>]
    gearman_worker.work()
  File "/Library/Python/2.7/site-packages/gearman/worker.py", line 83, in work
    continue_working = self.poll_connections_until_stopped(worker_connections, continue_while_connections_alive, timeout=poll_timeout)
  File "/Library/Python/2.7/site-packages/gearman/connection_manager.py", line 203, in poll_connections_until_stopped
    raise ServerUnavailable('Found no valid connections in list: %r' % self.connection_list)
gearman.errors.ServerUnavailable: Found no valid connections in list: [<GearmanConnection 127.0.0.1:4730 connected=False>]
Traceback (most recent call last):
  File "gearman_worker_save_file.py", line 62, in <module>
Traceback (most recent call last):
  File "gearman_worker_read_file.py", line 72, in <module>
    gearman_worker.work()
  File "/Library/Python/2.7/site-packages/gearman/worker.py", line 83, in work
    gearman_worker.work()
  File "/Library/Python/2.7/site-packages/gearman/worker.py", line 83, in work
    continue_working = self.poll_connections_until_stopped(worker_connections, continue_while_connections_alive, timeout=poll_timeout)
  File "/Library/Python/2.7/site-packages/gearman/connection_manager.py", line 203, in poll_connections_until_stopped
    continue_working = self.poll_connections_until_stopped(worker_connections, continue_while_connections_alive, timeout=poll_timeout)
  File "/Library/Python/2.7/site-packages/gearman/connection_manager.py", line 203, in poll_connections_until_stopped
    raise ServerUnavailable('Found no valid connections in list: %r' % self.connection_list)
gearman.errors.    ServerUnavailableraise ServerUnavailable('Found no valid connections in list: %r' % self.connection_list)
: Found no valid connections in list: [<GearmanConnection 127.0.0.1:4730 connected=False>]
gearman.errors.ServerUnavailable: Found no valid connections in list: [<GearmanConnection 127.0.0.1:4730 connected=False>]
